Workbook

Sheet Read Me
A1: Game Night Tracker
A3: How to use:
A4: • Add each new game as a row at the bottom of the 'Game Log' sheet (yellow-marked columns are the ones you fill in).
A5: • Winners: player name, or several separated by commas (e.g. 'Ian, Lucanor'). For co-op games (Pandemic) enter 'Win' or 'Loss'.
A6: • Players: everyone at the table, separated by commas.
A7: • The 'Leaderboard' and 'Games' sheets update automatically — no need to touch them. Their formulas cover rows up to 3000.
A9: Notes on this rebuild (July 2026):
A10: • 677 games imported from the original file (Mar 2015 – Jun 2026), one row per game.
A11: • Name/game spellings were normalized ('Munchkin ' → 'Munchkin', '*ennis' → 'Dennis', 'PAul' → 'Paul', etc.).
A12: • Where a row had no attendance recorded, the winner was assumed present. 8 co-op games have no attendance data.
A13: • One 2015 entry read 'Ling of' and was assumed to be Kings of Tokyo (noted on that row).

Sheet Game Log
A1: Date | B1: Game | C1: Winners | D1: Players | E1: # Players | F1: Notes
A2: 42067 | B2: Pandemic | C2: Dennis, Ian, Johnny, Lucanor | D2: Lucanor, Dennis, Ian, Johnny | E2: =IF($D2="",0,LEN($D2)-LEN(SUBSTITUTE($D2,",",""))+1) -> 4
A3: 42067 | B3: Tsuro | C3: Lucanor | D3: Lucanor, Dennis, Ian, Johnny | E3: =IF($D3="",0,LEN($D3)-LEN(SUBSTITUTE($D3,",",""))+1) -> 4
A4: 42067 | B4: Tsuro | C4: Ian | D4: Ian | E4: =IF($D4="",0,LEN($D4)-LEN(SUBSTITUTE($D4,",",""))+1) -> 1
A5: 42068 | B5: Qwirkle | C5: Johnny | D5: Johnny | E5: =IF($D5="",0,LEN($D5)-LEN(SUBSTITUTE($D5,",",""))+1) -> 1
A6: 42068 | B6: Pandemic | C6: Dennis, Ian, Martin, Lucanor | D6: Lucanor, Dennis, Ian, Mark, Martin, Johnny | E6: =IF($D6="",0,LEN($D6)-LEN(SUBSTITUTE($D6,",",""))+1) -> 6
A7: 42070 | B7: Shogun | C7: Lucanor | D7: Lucanor, Dennis, Mark, Johnny | E7: =IF($D7="",0,LEN($D7)-LEN(SUBSTITUTE($D7,",",""))+1) -> 4
A8: 42070 | B8: Qwirkle | C8: Lucanor | D8: Lucanor, Dennis, Ian, Mark, Johnny | E8: =IF($D8="",0,LEN($D8)-LEN(SUBSTITUTE($D8,",",""))+1) -> 5
A9: 42071 | B9: Kings of Tokyo | C9: Ian | D9: Lucanor, Dennis, Ian, Johnny | E9: =IF($D9="",0,LEN($D9)-LEN(SUBSTITUTE($D9,",",""))+1) -> 4
A10: 42071 | B10: Kings of Tokyo | C10: Johnny | D10: Lucanor, Dennis, Ian, Johnny | E10: =IF($D10="",0,LEN($D10)-LEN(SUBSTITUTE($D10,",",""))+1) -> 4
A11: 42071 | B11: Qwirkle | C11: Ian, Johnny, Dennis | D11: Lucanor, Dennis, Ian, Mark, Johnny | E11: =IF($D11="",0,LEN($D11)-LEN(SUBSTITUTE($D11,",",""))+1) -> 5
A12: 42071 | B12: Kings of Tokyo | C12: Lucanor | D12: Lucanor, Dennis, Ian, Mark | E12: =IF($D12="",0,LEN($D12)-LEN(SUBSTITUTE($D12,",",""))+1) -> 4
A13: 42071 | B13: Kings of Tokyo | C13: Dennis | D13: Lucanor, Dennis, Ian, Mark | E13: =IF($D13="",0,LEN($D13)-LEN(SUBSTITUTE($D13,",",""))+1) -> 4
... A33: 42139 | B33: Pandemic | C33: Ian, Dennis, Lucanor | D33: Ian, Dennis, Lucanor | E33: =IF($D33="",0,LEN($D33)-LEN(SUBSTITUTE($D33,",",""))+1) -> 3
A34: 42146 | B34: Pandemic | C34: Loss | E34: =IF($D34="",0,LEN($D34)-LEN(SUBSTITUTE($D34,",",""))+1) -> 0
A35: 42146 | B35: Pandemic | C35: Johnny, Lucanor, Dennis | D35: Dennis, Ian, Mark, Johnny, Lucanor | E35: =IF($D35="",0,LEN($D35)-LEN(SUBSTITUTE($D35,",",""))+1) -> 5
A36: 42146 | B36: Shogun | C36: Dennis | D36: Lucanor, Dennis, Ian, Mark, Martin | E36: =IF($D36="",0,LEN($D36)-LEN(SUBSTITUTE($D36,",",""))+1) -> 5
A37: 42147 | B37: Risk | C37: Mark | D37: Lucanor, Dennis, Ian, Mark, Johnny | E37: =IF($D37="",0,LEN($D37)-LEN(SUBSTITUTE($D37,",",""))+1) -> 5
A38: 42153 | B38: Shogun | C38: Mark | D38: Lucanor, Ian, Martin, Mark | E38: =IF($D38="",0,LEN($D38)-LEN(SUBSTITUTE($D38,",",""))+1) -> 4
A39: 42168 | B39: Smashup | C39: Martin | D39: Dennis, Gavin, Johnny, Martin | E39: =IF($D39="",0,LEN($D39)-LEN(SUBSTITUTE($D39,",",""))+1) -> 4
A40: 42175 | B40: Risk | C40: Dennis | D40: Lucanor, Dennis, Ian, Johnny | E40: =IF($D40="",0,LEN($D40)-LEN(SUBSTITUTE($D40,",",""))+1) -> 4
A41: 42182 | B41: Risk | C41: Lucanor | D41: Lucanor, Dennis, Ian, Johnny | E41: =IF($D41="",0,LEN($D41)-LEN(SUBSTITUTE($D41,",",""))+1) -> 4
A42: 42186 | B42: Smashup | C42: Lucanor | D42: Lucanor, Dennis, Ian | E42: =IF($D42="",0,LEN($D42)-LEN(SUBSTITUTE($D42,",",""))+1) -> 3
A43: 42186 | B43: Jamb | C43: Dennis | D43: Lucanor, Dennis, Mark, Martin | E43: =IF($D43="",0,LEN($D43)-LEN(SUBSTITUTE($D43,",",""))+1) -> 4
A44: 42193 | B44: Smashup | C44: Lucanor | D44: Lucanor, Dennis, Mark | E44: =IF($D44="",0,LEN($D44)-LEN(SUBSTITUTE($D44,",",""))+1) -> 3
A45: 42193 | B45: Kings of Tokyo | C45: Dennis | D45: Lucanor, Dennis, Mark | E45: =IF($D45="",0,LEN($D45)-LEN(SUBSTITUTE($D45,",",""))+1) -> 3
A46: 42193 | B46: Kings of Tokyo | C46: Mark | D46: Lucanor, Dennis, Mark | E46: =IF($D46="",0,LEN($D46)-LEN(SUBSTITUTE($D46,",",""))+1) -> 3
... A102: 42273 | B102: Kings of Tokyo | C102: Lucanor | D102: Lucanor | E102: =IF($D102="",0,LEN($D102)-LEN(SUBSTITUTE($D102,",",""))+1) -> 1
A103: 42273 | B103: Pandemic | C103: Loss | E103: =IF($D103="",0,LEN($D103)-LEN(SUBSTITUTE($D103,",",""))+1) -> 0
A104: 42273 | B104: Pandemic | C104: Loss | D104: Dennis, Ian, Mark, Paul, Johnny | E104: =IF($D104="",0,LEN($D104)-LEN(SUBSTITUTE($D104,",",""))+1) -> 5
A105: 42280 | B105: Qwirkle | C105: Dennis | D105: Dennis, Ian, Mark, Paul, Johnny | E105: =IF($D105="",0,LEN($D105)-LEN(SUBSTITUTE($D105,",",""))+1) -> 5
A106: 42280 | B106: Qwirkle | C106: Johnny | D106: Dennis, Ian, Mark, Johnny | E106: =IF($D106="",0,LEN($D106)-LEN(SUBSTITUTE($D106,",",""))+1) -> 4
A107: 42280 | B107: Kings of Tokyo | C107: Johnny | D107: Lucanor, Dennis, Johnny | E107: =IF($D107="",0,LEN($D107)-LEN(SUBSTITUTE($D107,",",""))+1) -> 3
A108: 42289 | B108: Jamb | C108: Lucanor | D108: Lucanor, Dennis, Ian, Mark, Johnny | E108: =IF($D108="",0,LEN($D108)-LEN(SUBSTITUTE($D108,",",""))+1) -> 5 | F108: Complete Card by Lucanor
A109: 42295 | B109: Kings of Tokyo | C109: Lucanor | D109: Lucanor | E109: =IF($D109="",0,LEN($D109)-LEN(SUBSTITUTE($D109,",",""))+1) -> 1
A110: 42295 | B110: Pandemic | C110: Win, Lucanor, Mark, Dennis, Ian | D110: Lucanor, Dennis, Ian, Mark | E110: =IF($D110="",0,LEN($D110)-LEN(SUBSTITUTE($D110,",",""))+1) -> 4
A111: 42295 | B111: Roll For It | C111: Ian | D111: Lucanor, Dennis, Ian, Mark | E111: =IF($D111="",0,LEN($D111)-LEN(SUBSTITUTE($D111,",",""))+1) -> 4
A112: 42302 | B112: Catan: Star Trek | C112: Ian | D112: Lucanor, Dennis, Ian, Mark | E112: =IF($D112="",0,LEN($D112)-LEN(SUBSTITUTE($D112,",",""))+1) -> 4
A113: 42302 | B113: Kings of Tokyo | C113: Mark | D113: Lucanor, Dennis, Ian, Mark | E113: =IF($D113="",0,LEN($D113)-LEN(SUBSTITUTE($D113,",",""))+1) -> 4
A114: 42302 | B114: Jamb | C114: Lucanor | D114: Lucanor, Dennis, Ian, Mark, Gavin, Johnny | E114: =IF($D114="",0,LEN($D114)-LEN(SUBSTITUTE($D114,",",""))+1) -> 6
...

Sheet Leaderboard
A1: Player | B1: Wins | C1: Games Played | D1: Win % | E1: Wins This Year | F1: Games This Year | G1: Win % This Year
A2: Lucanor | B2: =SUMPRODUCT(--ISNUMBER(SEARCH(", "&$A2&", ",", "&'Game Log'!$C$2:$C$3000&", "))) -> 290 | C2: =SUMPRODUCT(--ISNUMBER(SEARCH(", "&$A2&", ",", "&'Game Log'!$D$2:$D$3000&", "))) -> 622 | D2: =IF(C2=0,"",B2/C2) -> 0.46623794 | E2: =SUMPRODUCT(--ISNUMBER(SEARCH(", "&$A2&", ",", "&'Game Log'!$C$2:$C$3000&", ")),--(YEAR('Game Log'!$A$2:$A$3000+0)=YEAR(TODAY()))) -> 18 | F2: =SUMPRODUCT(--ISNUMBER(SEARCH(", "&$A2&", ",", "&'Game Log'!$D$2:$D$3000&", ")),--(YEAR('Game Log'!$A$2:$A$3000+0)=YEAR(TODAY()))) -> 36 | G2: =IF(F2=0,"",E2/F2) -> 0.5
A3: Dennis | B3: =SUMPRODUCT(--ISNUMBER(SEARCH(", "&$A3&", ",", "&'Game Log'!$C$2:$C$3000&", "))) -> 236 | C3: =SUMPRODUCT(--ISNUMBER(SEARCH(", "&$A3&", ",", "&'Game Log'!$D$2:$D$3000&", "))) -> 650 | D3: =IF(C3=0,"",B3/C3) -> 0.36307692 | E3: =SUMPRODUCT(--ISNUMBER(SEARCH(", "&$A3&", ",", "&'Game Log'!$C$2:$C$3000&", ")),--(YEAR('Game Log'!$A$2:$A$3000+0)=YEAR(TODAY()))) -> 13 | F3: =SUMPRODUCT(--ISNUMBER(SEARCH(", "&$A3&", ",", "&'Game Log'!$D$2:$D$3000&", ")),--(YEAR('Game Log'!$A$2:$A$3000+0)=YEAR(TODAY()))) -> 36 | G3: =IF(F3=0,"",E3/F3) -> 0.36111111
A4: Ian | B4: =SUMPRODUCT(--ISNUMBER(SEARCH(", "&$A4&", ",", "&'Game Log'!$C$2:$C$3000&", "))) -> 85 | C4: =SUMPRODUCT(--ISNUMBER(SEARCH(", "&$A4&", ",", "&'Game Log'!$D$2:$D$3000&", "))) -> 382 | D4: =IF(C4=0,"",B4/C4) -> 0.22251309 | E4: =SUMPRODUCT(--ISNUMBER(SEARCH(", "&$A4&", ",", "&'Game Log'!$C$2:$C$3000&", ")),--(YEAR('Game Log'!$A$2:$A$3000+0)=YEAR(TODAY()))) -> 4 | F4: =SUMPRODUCT(--ISNUMBER(SEARCH(", "&$A4&", ",", "&'Game Log'!$D$2:$D$3000&", ")),--(YEAR('Game Log'!$A$2:$A$3000+0)=YEAR(TODAY()))) -> 29 | G4: =IF(F4=0,"",E4/F4) -> 0.13793103
A5: Mark | B5: =SUMPRODUCT(--ISNUMBER(SEARCH(", "&$A5&", ",", "&'Game Log'!$C$2:$C$3000&", "))) -> 34 | C5: =SUMPRODUCT(--ISNUMBER(SEARCH(", "&$A5&", ",", "&'Game Log'!$D$2:$D$3000&", "))) -> 202 | D5: =IF(C5=0,"",B5/C5) -> 0.16831683 | E5: =SUMPRODUCT(--ISNUMBER(SEARCH(", "&$A5&", ",", "&'Game Log'!$C$2:$C$3000&", ")),--(YEAR('Game Log'!$A$2:$A$3000+0)=YEAR(TODAY()))) -> 1 | F5: =SUMPRODUCT(--ISNUMBER(SEARCH(", "&$A5&", ",", "&'Game Log'!$D$2:$D$3000&", ")),--(YEAR('Game Log'!$A$2:$A$3000+0)=YEAR(TODAY()))) -> 7 | G5: =IF(F5=0,"",E5/F5) -> 0.14285714
A6: Alistair | B6: =SUMPRODUCT(--ISNUMBER(SEARCH(", "&$A6&", ",", "&'Game Log'!$C$2:$C$3000&", "))) -> 3 | C6: =SUMPRODUCT(--ISNUMBER(SEARCH(", "&$A6&", ",", "&'Game Log'!$D$2:$D$3000&", "))) -> 28 | D6: =IF(C6=0,"",B6/C6) -> 0.10714286 | E6: =SUMPRODUCT(--ISNUMBER(SEARCH(", "&$A6&", ",", "&'Game Log'!$C$2:$C$3000&", ")),--(YEAR('Game Log'!$A$2:$A$3000+0)=YEAR(TODAY()))) -> 0 | F6: =SUMPRODUCT(--ISNUMBER(SEARCH(", "&$A6&", ",", "&'Game Log'!$D$2:$D$3000&", ")),--(YEAR('Game Log'!$A$2:$A$3000+0)=YEAR(TODAY()))) -> 8 | G6: =IF(F6=0,"",E6/F6) -> 0
A7: Martin | B7: =SUMPRODUCT(--ISNUMBER(SEARCH(", "&$A7&", ",", "&'Game Log'!$C$2:$C$3000&", "))) -> 7 | C7: =SUMPRODUCT(--ISNUMBER(SEARCH(", "&$A7&", ",", "&'Game Log'!$D$2:$D$3000&", "))) -> 62 | D7: =IF(C7=0,"",B7/C7) -> 0.11290323 | E7: =SUMPRODUCT(--ISNUMBER(SEARCH(", "&$A7&", ",", "&'Game Log'!$C$2:$C$3000&", ")),--(YEAR('Game Log'!$A$2:$A$3000+0)=YEAR(TODAY()))) -> 0 | F7: =SUMPRODUCT(--ISNUMBER(SEARCH(", "&$A7&", ",", "&'Game Log'!$D$2:$D$3000&", ")),--(YEAR('Game Log'!$A$2:$A$3000+0)=YEAR(TODAY()))) -> 2 | G7: =IF(F7=0,"",E7/F7) -> 0
A8: Gavin | B8: =SUMPRODUCT(--ISNUMBER(SEARCH(", "&$A8&", ",", "&'Game Log'!$C$2:$C$3000&", "))) -> 2 | C8: =SUMPRODUCT(--ISNUMBER(SEARCH(", "&$A8&", ",", "&'Game Log'!$D$2:$D$3000&", "))) -> 37 | D8: =IF(C8=0,"",B8/C8) -> 0.054054054 | E8: =SUMPRODUCT(--ISNUMBER(SEARCH(", "&$A8&", ",", "&'Game Log'!$C$2:$C$3000&", ")),--(YEAR('Game Log'!$A$2:$A$3000+0)=YEAR(TODAY()))) -> 0 | F8: =SUMPRODUCT(--ISNUMBER(SEARCH(", "&$A8&", ",", "&'Game Log'!$D$2:$D$3000&", ")),--(YEAR('Game Log'!$A$2:$A$3000+0)=YEAR(TODAY()))) -> 0 | G8: =IF(F8=0,"",E8/F8)
A9: Rod | B9: =SUMPRODUCT(--ISNUMBER(SEARCH(", "&$A9&", ",", "&'Game Log'!$C$2:$C$3000&", "))) -> 0 | C9: =SUMPRODUCT(--ISNUMBER(SEARCH(", "&$A9&", ",", "&'Game Log'!$D$2:$D$3000&", "))) -> 2 | D9: =IF(C9=0,"",B9/C9) -> 0 | E9: =SUMPRODUCT(--ISNUMBER(SEARCH(", "&$A9&", ",", "&'Game Log'!$C$2:$C$3000&", ")),--(YEAR('Game Log'!$A$2:$A$3000+0)=YEAR(TODAY()))) -> 0 | F9: =SUMPRODUCT(--ISNUMBER(SEARCH(", "&$A9&", ",", "&'Game Log'!$D$2:$D$3000&", ")),--(YEAR('Game Log'!$A$2:$A$3000+0)=YEAR(TODAY()))) -> 0 | G9: =IF(F9=0,"",E9/F9)
A10: Miguel | B10: =SUMPRODUCT(--ISNUMBER(SEARCH(", "&$A10&", ",", "&'Game Log'!$C$2:$C$3000&", "))) -> 0 | C10: =SUMPRODUCT(--ISNUMBER(SEARCH(", "&$A10&", ",", "&'Game Log'!$D$2:$D$3000&", "))) -> 2 | D10: =IF(C10=0,"",B10/C10) -> 0 | E10: =SUMPRODUCT(--ISNUMBER(SEARCH(", "&$A10&", ",", "&'Game Log'!$C$2:$C$3000&", ")),--(YEAR('Game Log'!$A$2:$A$3000+0)=YEAR(TODAY()))) -> 0 | F10: =SUMPRODUCT(--ISNUMBER(SEARCH(", "&$A10&", ",", "&'Game Log'!$D$2:$D$3000&", ")),--(YEAR('Game Log'!$A$2:$A$3000+0)=YEAR(TODAY()))) -> 0 | G10: =IF(F10=0,"",E10/F10)
A11: Andy | B11: =SUMPRODUCT(--ISNUMBER(SEARCH(", "&$A11&", ",", "&'Game Log'!$C$2:$C$3000&", "))) -> 1 | C11: =SUMPRODUCT(--ISNUMBER(SEARCH(", "&$A11&", ",", "&'Game Log'!$D$2:$D$3000&", "))) -> 4 | D11: =IF(C11=0,"",B11/C11) -> 0.25 | E11: =SUMPRODUCT(--ISNUMBER(SEARCH(", "&$A11&", ",", "&'Game Log'!$C$2:$C$3000&", ")),--(YEAR('Game Log'!$A$2:$A$3000+0)=YEAR(TODAY()))) -> 0 | F11: =SUMPRODUCT(--ISNUMBER(SEARCH(", "&$A11&", ",", "&'Game Log'!$D$2:$D$3000&", ")),--(YEAR('Game Log'!$A$2:$A$3000+0)=YEAR(TODAY()))) -> 0 | G11: =IF(F11=0,"",E11/F11)
A12: Paul | B12: =SUMPRODUCT(--ISNUMBER(SEARCH(", "&$A12&", ",", "&'Game Log'!$C$2:$C$3000&", "))) -> 5 | C12: =SUMPRODUCT(--ISNUMBER(SEARCH(", "&$A12&", ",", "&'Game Log'!$D$2:$D$3000&", "))) -> 26 | D12: =IF(C12=0,"",B12/C12) -> 0.19230769 | E12: =SUMPRODUCT(--ISNUMBER(SEARCH(", "&$A12&", ",", "&'Game Log'!$C$2:$C$3000&", ")),--(YEAR('Game Log'!$A$2:$A$3000+0)=YEAR(TODAY()))) -> 0 | F12: =SUMPRODUCT(--ISNUMBER(SEARCH(", "&$A12&", ",", "&'Game Log'!$D$2:$D$3000&", ")),--(YEAR('Game Log'!$A$2:$A$3000+0)=YEAR(TODAY()))) -> 0 | G12: =IF(F12=0,"",E12/F12)
A13: Andre | B13: =SUMPRODUCT(--ISNUMBER(SEARCH(", "&$A13&", ",", "&'Game Log'!$C$2:$C$3000&", "))) -> 0 | C13: =SUMPRODUCT(--ISNUMBER(SEARCH(", "&$A13&", ",", "&'Game Log'!$D$2:$D$3000&", "))) -> 4 | D13: =IF(C13=0,"",B13/C13) -> 0 | E13: =SUMPRODUCT(--ISNUMBER(SEARCH(", "&$A13&", ",", "&'Game Log'!$C$2:$C$3000&", ")),--(YEAR('Game Log'!$A$2:$A$3000+0)=YEAR(TODAY()))) -> 0 | F13: =SUMPRODUCT(--ISNUMBER(SEARCH(", "&$A13&", ",", "&'Game Log'!$D$2:$D$3000&", ")),--(YEAR('Game Log'!$A$2:$A$3000+0)=YEAR(TODAY()))) -> 0 | G13: =IF(F13=0,"",E13/F13)
A14: Johnny | B14: =SUMPRODUCT(--ISNUMBER(SEARCH(", "&$A14&", ",", "&'Game Log'!$C$2:$C$3000&", "))) -> 21 | C14: =SUMPRODUCT(--ISNUMBER(SEARCH(", "&$A14&", ",", "&'Game Log'!$D$2:$D$3000&", "))) -> 97 | D14: =IF(C14=0,"",B14/C14) -> 0.21649485 | E14: =SUMPRODUCT(--ISNUMBER(SEARCH(", "&$A14&", ",", "&'Game Log'!$C$2:$C$3000&", ")),--(YEAR('Game Log'!$A$2:$A$3000+0)=YEAR(TODAY()))) -> 0 | F14: =SUMPRODUCT(--ISNUMBER(SEARCH(", "&$A14&", ",", "&'Game Log'!$D$2:$D$3000&", ")),--(YEAR('Game Log'!$A$2:$A$3000+0)=YEAR(TODAY()))) -> 0 | G14: =IF(F14=0,"",E14/F14)
A16: Co-op games (Pandemic etc.)
A17: Team wins | B17: =COUNTIF('Game Log'!$C$2:$C$3000,"Win") -> 8
A18: Team losses | B18: =COUNTIF('Game Log'!$C$2:$C$3000,"Loss") -> 13

Sheet Games
A1: Game | B1: Times Played | C1: Last Played
A2: 7 Wonders | B2: =COUNTIF('Game Log'!$B$2:$B$3000,$A2) -> 17 | C2: =IF(B2=0,"",SUMPRODUCT(MAX(('Game Log'!$B$2:$B$3000=$A2)*'Game Log'!$A$2:$A$3000))) -> 46020
A3: Axis and Allies | B3: =COUNTIF('Game Log'!$B$2:$B$3000,$A3) -> 1 | C3: =IF(B3=0,"",SUMPRODUCT(MAX(('Game Log'!$B$2:$B$3000=$A3)*'Game Log'!$A$2:$A$3000))) -> 45266
A4: Backgammon | B4: =COUNTIF('Game Log'!$B$2:$B$3000,$A4) -> 12 | C4: =IF(B4=0,"",SUMPRODUCT(MAX(('Game Log'!$B$2:$B$3000=$A4)*'Game Log'!$A$2:$A$3000))) -> 42435
A5: Boxcars Ireland | B5: =COUNTIF('Game Log'!$B$2:$B$3000,$A5) -> 12 | C5: =IF(B5=0,"",SUMPRODUCT(MAX(('Game Log'!$B$2:$B$3000=$A5)*'Game Log'!$A$2:$A$3000))) -> 45913
A6: Boxcars UK | B6: =COUNTIF('Game Log'!$B$2:$B$3000,$A6) -> 106 | C6: =IF(B6=0,"",SUMPRODUCT(MAX(('Game Log'!$B$2:$B$3000=$A6)*'Game Log'!$A$2:$A$3000))) -> 46186
A7: Carcassonne | B7: =COUNTIF('Game Log'!$B$2:$B$3000,$A7) -> 33 | C7: =IF(B7=0,"",SUMPRODUCT(MAX(('Game Log'!$B$2:$B$3000=$A7)*'Game Log'!$A$2:$A$3000))) -> 45764
A8: Catan: Star Trek | B8: =COUNTIF('Game Log'!$B$2:$B$3000,$A8) -> 1 | C8: =IF(B8=0,"",SUMPRODUCT(MAX(('Game Log'!$B$2:$B$3000=$A8)*'Game Log'!$A$2:$A$3000))) -> 42302
A9: Colt Express | B9: =COUNTIF('Game Log'!$B$2:$B$3000,$A9) -> 6 | C9: =IF(B9=0,"",SUMPRODUCT(MAX(('Game Log'!$B$2:$B$3000=$A9)*'Game Log'!$A$2:$A$3000))) -> 45289
A10: Exploding Kittens | B10: =COUNTIF('Game Log'!$B$2:$B$3000,$A10) -> 1 | C10: =IF(B10=0,"",SUMPRODUCT(MAX(('Game Log'!$B$2:$B$3000=$A10)*'Game Log'!$A$2:$A$3000))) -> 42230
A11: Heat | B11: =COUNTIF('Game Log'!$B$2:$B$3000,$A11) -> 2 | C11: =IF(B11=0,"",SUMPRODUCT(MAX(('Game Log'!$B$2:$B$3000=$A11)*'Game Log'!$A$2:$A$3000))) -> 45268
A12: Jaipur | B12: =COUNTIF('Game Log'!$B$2:$B$3000,$A12) -> 1 | C12: =IF(B12=0,"",SUMPRODUCT(MAX(('Game Log'!$B$2:$B$3000=$A12)*'Game Log'!$A$2:$A$3000))) -> 45191
A13: Jamb | B13: =COUNTIF('Game Log'!$B$2:$B$3000,$A13) -> 125 | C13: =IF(B13=0,"",SUMPRODUCT(MAX(('Game Log'!$B$2:$B$3000=$A13)*'Game Log'!$A$2:$A$3000))) -> 46186
... A36: Zombie Dice | B36: =COUNTIF('Game Log'!$B$2:$B$3000,$A36) -> 23 | C36: =IF(B36=0,"",SUMPRODUCT(MAX(('Game Log'!$B$2:$B$3000=$A36)*'Game Log'!$A$2:$A$3000))) -> 45745
